Workbook

Sheet Read me
A1: Acro Skills Reference
A2: Glass House Dance acro chart, Levels 1–4 · for Sofia's grown-ups · same content as Acro-Skills-Reference.pdf
A4: What this is
A5: A reference for parents: what each move on the studio's chart is, how it's done, the drills coaches use, and where to watch it. It is not a home training plan; Sofia's teachers decide what she's ready for.
A7: Safety key (column 'Safety' on Skills and Drills)
A8: Home: fine at home on a carpet or mat.
A9: Home + adult: home only on a proper mat, with an adult nearby, once the teacher says she has it.
A10: Class only: only in class with a coach spotting. Flips, handsprings, aerials, headspins and all partner lifts are class only.
A12: Sheets
A13: Skills: one row per move on the chart (plus 2 bonus moves). Her group is Level 2–3, shaded pink. 'Ask teacher' = Yes means the name isn't a standard term we could confirm.
A14: Drills: the standard drills for each move family, with their own safety rating.
A15: Links: videos, articles and Pinterest ideas per family. Click the title to open. Pinterest links are picture and short-clip ideas, often reposts, not instructions.
... A25: Web research in October 2026. Every link came from search results, but none could be opened to check them, so a few may have moved or disappeared. 'Machine' has no link. Safety ratings were reviewed and tightened for a 9-year-old.

Sheet Skills
A1: Section | B1: Family | C1: Level | D1: Her group | E1: Move | F1: What it is | G1: How it's done | H1: Common faults | I1: Safety | J1: Why this rating | K1: Before this | L1: Ask teacher | M1: Status | N1: Notes
A2: Acro basics | B2: Handstand | C2: Level 1 | E2: Handstand: clap feet | F2: I could not find a written definition of this exact term; ask the teacher. From the name it most likely means kicking to a handstand, opening the legs and tapping or clapping the feet together once at the top before stepping down. | G2: 1. Start in a lunge with arms straight up by the ears. 2. Reach long to the floor, place both hands shoulder-width apart and kick up. 3. At the top, keep the arms locked and the eyes on the floor between the hands. 4. Do the foot action the teacher shows (most likely legs open, then feet tap together). 5. Step down one leg at a time back into the lunge. | H2: • Bending the elbows when the legs move • Kicking too hard and over-balancing • Looking forward or tucking the chin, which collapses the shape | I2: Home + adult | J2: She is fully upside down with her weight on her wrists and shoulders, so practise only on a mat with clear space and an adult close by, and only once her teacher says her kick-up and safe exit (step down or cartwheel out) are solid. | K2: Strong plank and hollow-body hold; Wrist and shoulder warm-up and mobility (arms fully straight by the ears); Lunge kick-up to a T-shape or donkey kicks; Wall handstand with good alignment | L2: Yes
A3: Acro basics | B3: Handstand | C3: Level 2 | D3: Yes | E3: Handstand: double stag | F3: A handstand held in a split shape with both knees bent, borrowing the 'double stag' leg shape from dance leaps. A regular stag handstand bends only the front knee; I found it described but not 'double stag' by name, so ask the teacher to confirm the exact shape. | G3: 1. Kick to a handstand from a lunge with arms locked. 2. Split the legs front and back at the top. 3. Bend both knees so the feet point toward each other behind and in front, like a double stag leap upside down. 4. Hold briefly with the hips stacked over the shoulders. 5. Straighten the legs and step down with control. | H3: • Letting the hips sag or the back arch too much when the knees bend • Uneven split (one leg drifts sideways) • Rushing the shape so it is not clearly shown | I3: Home + adult | J3: She is fully upside down with her weight on her wrists and shoulders, so practise only on a mat with clear space and an adult close by, and only once her teacher says her kick-up and safe exit (step down or cartwheel out) are solid. | K3: Strong plank and hollow-body hold; Wrist and shoulder warm-up and mobility (arms fully straight by the ears); Lunge kick-up to a T-shape or donkey kicks; Wall handstand with good alignment | L3: Yes
A4: Acro basics | B4: Handstand | C4: Level 3 | D4: Yes | E4: Handstand: helicopter | F4: Not a standard term I could verify; ask the teacher. On this chart 'helicopter' also appears on cartwheels, where it means switching the legs while upside down so the second leg lands first, so this may be a handstand with a leg switch, but I could not confirm that. | G4: 1. Ask the teacher to demonstrate the exact action and entry. 2. It builds on a confident handstand with locked arms and a controlled exit. 3. Practise only the version and progression the teacher sets. | H4: • Attempting it before the basic handstand and exits are solid • Losing straight arms while the legs move | I4: Home + adult | J4: She is fully upside down with her weight on her wrists and shoulders, so practise only on a mat with clear space and an adult close by, and only once her teacher says her kick-up and safe exit (step down or cartwheel out) are solid. | K4: Strong plank and hollow-body hold; Wrist and shoulder warm-up and mobility (arms fully straight by the ears); Lunge kick-up to a T-shape or donkey kicks; Wall handstand with good alignment | L4: Yes
A5: Acro basics | B5: Handstand | C5: Level 4 | E5: Handstand: walking (Level 4) | F5: Walking forward on the hands while staying in a handstand. The chart lists walking at Level 3 and Level 4; the difference (likely distance or control) is set by the studio, so ask the teacher what the Level 4 standard is. Acrobatic Arts places handstand walking in its Levels 7-8. | G5: 1. Kick to a straight handstand with the shoulders pushed tall. 2. Let the body tip very slightly forward, just past balance. 3. Take small steps with the hands to stay underneath the feet. 4. Keep the legs together and squeezed, eyes on the floor ahead of the hands. 5. Step down or roll out with control when finished. | H5: • Big, rushed hand steps that let the legs fall over • Arching the back into a banana shape • Bending the elbows as the weight shifts from hand to hand | I5: Home + adult | J5: She is fully upside down with her weight on her wrists and shoulders, so practise only on a mat with clear space and an adult close by, and only once her teacher says her kick-up and safe exit (step down or cartwheel out) are solid. | K5: Strong plank and hollow-body hold; Wrist and shoulder warm-up and mobility (arms fully straight by the ears); Lunge kick-up to a T-shape or donkey kicks; Wall handstand with good alignment | L5: Yes
A6: Acro basics | B6: Handstand | C6: Level 3 | D6: Yes | E6: Handstand: walking (Level 3) | F6: The first stage of handstand walking: a few controlled hand steps from a kick-up. The exact Level 3 target (number of steps or distance) is set by the studio, so ask the teacher. | G6: 1. Kick up to handstand with arms locked and body tight. 2. Shift the weight slightly forward over the fingers. 3. Take short hand steps, keeping the shoulders over the hands. 4. Come down by stepping one leg down. | H6: • Starting to walk before finding balance • Loose legs that swing apart • Shoulders not fully open, so the body piles forward | I6: Home + adult | J6: She is fully upside down with her weight on her wrists and shoulders, so practise only on a mat with clear space and an adult close by, and only once her teacher says her kick-up and safe exit (step down or cartwheel out) are solid. | K6: Strong plank and hollow-body hold; Wrist and shoulder warm-up and mobility (arms fully straight by the ears); Lunge kick-up to a T-shape or donkey kicks; Wall handstand with good alignment | L6: Yes
A7: Acro basics | B7: Handstand hold | C7: Level 2 | D7: Yes | E7: Handstand hold: 5 sec | F7: A freestanding handstand held still for five seconds. | G7: 1. Kick up from a lunge with arms locked by the ears. 2. Find the balance point with the hips stacked over the shoulders. 3. Squeeze the legs together, point the toes and press the floor away. 4. Correct small wobbles with the fingers, not the arms. 5. Count to five, then step down. | H7: • Banana-shaped back • Bent arms or sunken shoulders • Correcting balance by walking the hands | I7: Home + adult | J7: Holding a handstand loads the wrists and shoulders and a fall can be sudden, so practise at a wall or on a mat with an adult nearby once the teacher is happy with her form. | K7: Clean kick-up to handstand; Hollow-body hold and plank; Wall handstand of 20-30 seconds; Safe exit (step down or cartwheel out)
A8: Acro basics | B8: Handstand hold | C8: Level 3 | D8: Yes | E8: Handstand hold: shoulder taps | F8: In a handstand (usually first at the wall), lifting one hand to tap the opposite shoulder, then switching. It builds one-arm strength and balance. | G8: 1. Set up in a wall handstand, toes touching the wall, or a pike position on a box first. 2. Shift the weight onto one hand by leaning slightly into that shoulder. 3. Lift the free hand and tap the opposite shoulder. 4. Place it back down and repeat on the other side. 5. Keep the body tight and straight throughout. | H8: • Hips swinging side to side • Bending the support arm • Holding the breath and rushing the taps | I8: Home + adult | J8: Holding a handstand loads the wrists and shoulders and a fall can be sudden, so practise at a wall or on a mat with an adult nearby once the teacher is happy with her form. | K8: Clean kick-up to handstand; Hollow-body hold and plank; Wall handstand of 20-30 seconds; Safe exit (step down or cartwheel out)
A9: Acro basics | B9: Handstand hold | C9: Level 4 | E9: Handstand hold: 30 sec | F9: A freestanding handstand held still for thirty seconds, which needs good endurance and fine balance control. | G9: 1. Kick up to a straight handstand. 2. Push tall through the shoulders and keep the ribs pulled in. 3. Breathe steadily and use the fingertips and heel of the hand to balance. 4. Hold the shape for 30 seconds, then step down. | H9: • Shape gradually arching as she tires • Elbows softening • Stopping breathing | I9: Home + adult | J9: Holding a handstand loads the wrists and shoulders and a fall can be sudden, so practise at a wall or on a mat with an adult nearby once the teacher is happy with her form. | K9: Clean kick-up to handstand; Hollow-body hold and plank; Wall handstand of 20-30 seconds; Safe exit (step down or cartwheel out)
A10: Acro basics | B10: Cartwheel | C10: Level 1 | E10: Cartwheel: both sides | F10: A standard cartwheel performed equally well leading with the right and with the left. | G10: 1. Start in a lunge, arms straight up by the ears. 2. Reach forward and place the first hand, then the second, in a line on the floor. 3. Kick the back leg up and push off the front leg so the legs pass over in a wide straddle, hips over the hands. 4. Land one foot at a time back in a lunge, arms still up. 5. Repeat leading with the other side. | H10: • Hands placed side by side instead of in a line, so the cartwheel curves • Bent knees and piked hips (legs not passing straight over the top) • Only practising the strong side | I10: Home + adult | J10: Basic and one-handed cartwheels are fine on grass or a mat with an adult nearby once she is confident, but the helicopter versions add a twist while upside down and should stay in class with a coach until the teacher clears them. | K10: Lunge and kick to handstand; Wrist and shoulder strength (bunny hops, wall handstand); Straddle and split flexibility; For one-handed and heli versions: a straight, clean cartwheel on both sides
A11: Acro basics | B11: Cartwheel | C11: Level 2 | D11: Yes | E11: Cartwheel: 1 handed | F11: A cartwheel using only one hand on the floor. The near-hand version (same side as the lead leg) is easier; the far-hand version leads toward no-handed skills. | G11: 1. Start from a lunge as for a normal cartwheel. 2. Place only the lead hand on the floor (usually the one on the same side as the lead leg). 3. Keep the free arm by the thigh or out to the side. 4. Kick over with straight legs and the hips stacked over the hand. 5. Land in a lunge one foot at a time. | H11: • Collapsing the supporting elbow • Turning the hips so it becomes a sloppy round-off • Not kicking high enough to get over the one hand | I11: Home + adult | J11: Basic and one-handed cartwheels are fine on grass or a mat with an adult nearby once she is confident, but the helicopter versions add a twist while upside down and should stay in class with a coach until the teacher clears them. | K11: Lunge and kick to handstand; Wrist and shoulder strength (bunny hops, wall handstand); Straddle and split flexibility; For one-handed and heli versions: a straight, clean cartwheel on both sides
A12: Acro basics | B12: Cartwheel | C12: Level 3 | D12: Yes | E12: Cartwheel: helicopter | F12: Starts like a cartwheel, but while upside down the legs scissor-switch so the leg that left the floor second lands first, giving a spinning 'helicopter' look. | G12: 1. What it looks like: a cartwheel entry, a quick leg switch in the air at the top, and a landing on the opposite leg to a normal cartwheel. 2. Parts the coach teaches: a strong, high cartwheel; split and straddle control; the timing of the leg switch while upside down. 3. The coach builds it in progressions on mats and spots it before she tries it alone. | H12: • Switching the legs too early, before the body is upside down • Bending the arms or dropping the shoulders during the switch • Landing off-line | I12: Home + adult | J12: Basic and one-handed cartwheels are fine on grass or a mat with an adult nearby once she is confident, but the helicopter versions add a twist while upside down and should stay in class with a coach until the teacher clears them. | K12: Lunge and kick to handstand; Wrist and shoulder strength (bunny hops, wall handstand); Straddle and split flexibility; For one-handed and heli versions: a straight, clean cartwheel on both sides
A13: Acro basics | B13: Cartwheel | C13: Level 4 | E13: Cartwheel: helicopter walkout | F13: Not a standard term I could verify; ask the teacher. It builds on the helicopter cartwheel, and 'walkout' probably refers to how the landing is finished, but I could not confirm the exact skill. | G13: 1. Ask the teacher to show the exact landing and finish. 2. Requires a clean helicopter cartwheel first. 3. Practise only in class with the teacher's progressions. | H13: • Attempting it before the basic heli is consistent | I13: Home + adult | J13: Basic and one-handed cartwheels are fine on grass or a mat with an adult nearby once she is confident, but the helicopter versions add a twist while upside down and should stay in class with a coach until the teacher clears them. | K13: Lunge and kick to handstand; Wrist and shoulder strength (bunny hops, wall handstand); Straddle and split flexibility; For one-handed and heli versions: a straight, clean cartwheel on both sides | L13: Yes
A14: Acro basics | B14: Round off | C14: Level 1 | E14: Round off | F14: A cartwheel that turns over the hands and lands on two feet together, facing the starting direction. | G14: 1. Take a lunge or a small hurdle and reach long. 2. Place the first hand, then the second hand turned in, as the body quarter-turns. 3. Kick through handstand and bring the legs together over the top. 4. Push from the shoulders and snap both feet down together. 5. Land facing back the way she came, arms up. | H14: • Legs not joining until after the landing • Hands placed too close to the feet, so the round off is short and low • Landing piked forward instead of upright | I14: Class only | J14: The round off has a push and a moment of flight when the legs snap down, and the no-hands version is an aerial-type skill, so these are learned in class with a coach; at home stick to cartwheels and floor drills. | K14: Strong straight cartwheel on both sides; Handstand with locked arms; Hurdle/skip entry; Snap-down from handstand
A15: Acro basics | B15: Round off | C15: Level 2 | D15: Yes | E15: Round off: brandy | F15: Not a standard term I could verify; ask the teacher. | G15: 1. Ask the teacher to demonstrate what the studio calls a 'brandy'. 2. It builds on a clean round off. | H15: • Trying it from a video guess before the teacher has shown it | I15: Class only | J15: The round off has a push and a moment of flight when the legs snap down, and the no-hands version is an aerial-type skill, so these are learned in class with a coach; at home stick to cartwheels and floor drills. | K15: Strong straight cartwheel on both sides; Handstand with locked arms; Hurdle/skip entry; Snap-down from handstand | L15: Yes
A16: Acro basics | B16: Round off | C16: Level 3 | D16: Yes | E16: Round off: bob (no hands) | F16: 'Bob' is not a standard term I could verify; ask the teacher. The chart's '(no hands)' suggests a round off performed without touching the floor, which would be an aerial-type skill. | G16: 1. What it looks like (if it is a no-handed round off): a round-off shape done in the air with both feet landing together. 2. Parts a coach teaches: a powerful hurdle, a strong round off, then hand-less progressions on mats with spotting. 3. Only attempted in class with a qualified coach. | H16: • Attempting flight skills without a coach and mats | I16: Class only | J16: The round off has a push and a moment of flight when the legs snap down, and the no-hands version is an aerial-type skill, so these are learned in class with a coach; at home stick to cartwheels and floor drills. | K16: Strong straight cartwheel on both sides; Handstand with locked arms; Hurdle/skip entry; Snap-down from handstand | L16: Yes
A17: Acro basics | B17: Bridge / walkover | C17: Level 1 | E17: Bridge | F17: Pushing up from lying on the back into an arch on straight arms and legs. | G17: 1. Lie on the back, knees bent, feet flat and hip-width apart. 2. Place hands by the ears, fingers pointing toward the feet. 3. Push through hands and feet to lift the body into an arch. 4. Straighten the arms and push the shoulders over the hands. 5. Lower slowly, tucking the chin to bring the back of the head down first. | H17: • Bent arms with the head hanging • Feet too far away or turned out • Shoulders behind the hands | I17: Class only | J17: Bridges from the floor are safe at home, but walkovers, kickovers from a back bend and especially the front aerial (a flying skill) are learned with a coach spotting because a mistake can drop her onto her head or neck. | K17: Bridge from the floor with straight arms and shoulders over the hands; Good back and shoulder flexibility; Front and side splits; Solid handstand; Bridge kickover before back walkover
A18: Acro basics | B18: Bridge / walkover | C18: Level 2 | D18: Yes | E18: Front walkover | F18: From standing, kicking through handstand in a split, arching over into a bridge on one foot, then standing up. | G18: 1. Start with arms by the ears and step into a lunge. 2. Place the hands and kick through a split handstand. 3. Let the back arch as the first foot reaches the floor behind. 4. Push through the shoulders and drive the hips forward to stand, head coming up last. 5. Finish balanced on one leg, other leg lifted, arms up. | H18: • Not enough shoulder flexibility, so she cannot stand up • Bending the arms • Bringing the head up first | I18: Class only | J18: Bridges from the floor are safe at home, but walkovers, kickovers from a back bend and especially the front aerial (a flying skill) are learned with a coach spotting because a mistake can drop her onto her head or neck. | K18: Bridge from the floor with straight arms and shoulders over the hands; Good back and shoulder flexibility; Front and side splits; Solid handstand; Bridge kickover before back walkover
A19: Acro basics | B19: Bridge / walkover | C19: Level 3 | D19: Yes | E19: Dive walkover | F19: A front walkover entered with a reach and push forward, so there is distance and a brief stretched moment before the hands land. | G19: 1. What it looks like: a long reach forward, a push from the floor, then a front walkover in a full split. 2. Coach cues from an Acrobatic Arts skill feature: distance after the push-off, full split in the walkover, head last to come up, balanced finish. 3. Taught in class on mats with spotting before it is done alone. | H19: • Diving down instead of out, so there is no distance • Loose split in the walkover • Head coming up early | I19: Class only | J19: Bridges from the floor are safe at home, but walkovers, kickovers from a back bend and especially the front aerial (a flying skill) are learned with a coach spotting because a mistake can drop her onto her head or neck. | K19: Bridge from the floor with straight arms and shoulders over the hands; Good back and shoulder flexibility; Front and side splits; Solid handstand; Bridge kickover before back walkover
A20: Acro basics | B20: Bridge / walkover | C20: Level 4 | E20: Front aerial | F20: A front walkover done completely in the air with no hands, landing one foot at a time. | G20: 1. What it looks like: a run or step, a powerful kick and a no-hands rotation forward in a split, landing in a lunge. 2. Parts the coach teaches: a strong kick and drive, a fast punch, chest position and split, often using a system such as the ADTA 4-step method. 3. Learned only on mats with a qualified coach spotting. | H20: • Throwing the head and chest down • Weak kick so the legs do not get round • Trying it without spotting | I20: Class only | J20: Bridges from the floor are safe at home, but walkovers, kickovers from a back bend and especially the front aerial (a flying skill) are learned with a coach spotting because a mistake can drop her onto her head or neck. | K20: Bridge from the floor with straight arms and shoulders over the hands; Good back and shoulder flexibility; Front and side splits; Solid handstand; Bridge kickover before back walkover
A21: Acro basics | B21: Bridge / walkover | C21: Level 1 | E21: Back bend, kickover | F21: Lowering from standing back into a bridge (back bend), then kicking one leg over to come up to standing. Gymnastics teaches a bridge kickover from the floor as the step before the back walkover. | G21: 1. Learn first from the floor: push up to a bridge, lift one leg, push from the shoulders and kick over to standing. 2. With a coach, practise reaching back from standing and lowering to the bridge. 3. From the bridge, shift the shoulders over the hands, lift one leg and kick over. 4. Land one foot at a time in a lunge. | H21: • Shoulders not over the hands, so she cannot kick over • Bending the elbows • Kicking with a bent leg | I21: Class only | J21: Bridges from the floor are safe at home, but walkovers, kickovers from a back bend and especially the front aerial (a flying skill) are learned with a coach spotting because a mistake can drop her onto her head or neck. | K21: Bridge from the floor with straight arms and shoulders over the hands; Good back and shoulder flexibility; Front and side splits; Solid handstand; Bridge kickover before back walkover
A22: Acro basics | B22: Bridge / walkover | C22: Level 2 | D22: Yes | E22: Back walkover | F22: From standing, arching back through a bridge with one leg lifted, kicking over through a split handstand and stepping down to stand. | G22: 1. Stand with one leg lifted in front and arms by the ears. 2. Arch back, reaching for the floor behind with straight arms. 3. As the hands land, push from the support leg and kick the lifted leg over. 4. Pass through a split handstand and step down one leg at a time. 5. Finish standing tall with arms up. | H22: • Sitting the hips back instead of pushing them forward • Bending the arms when the hands land • Looking for the floor too early | I22: Class only | J22: Bridges from the floor are safe at home, but walkovers, kickovers from a back bend and especially the front aerial (a flying skill) are learned with a coach spotting because a mistake can drop her onto her head or neck. | K22: Bridge from the floor with straight arms and shoulders over the hands; Good back and shoulder flexibility; Front and side splits; Solid handstand; Bridge kickover before back walkover
A23: Acro basics | B23: Bridge / walkover | C23: Level 3 | D23: Yes | E23: Monster walkover | F23: Not a standard term I could verify; ask the teacher. | G23: 1. Ask the teacher to demonstrate the studio's 'monster walkover'. 2. It is listed after the back walkover, so it likely needs a confident back walkover first. | H23: • Guessing the skill from videos before the teacher has shown it | I23: Class only | J23: Bridges from the floor are safe at home, but walkovers, kickovers from a back bend and especially the front aerial (a flying skill) are learned with a coach spotting because a mistake can drop her onto her head or neck. | K23: Bridge from the floor with straight arms and shoulders over the hands; Good back and shoulder flexibility; Front and side splits; Solid handstand; Bridge kickover before back walkover | L23: Yes
A24: Acro basics | B24: Front limber | C24: Level 1 | E24: Front limber | F24: Handstand, legs together over into a bridge, then stand up. | G24: 1. Start in a lunge with arms by the ears. 2. Kick to a handstand and bring the legs together. 3. Let the legs fall over together, arching the back, and land both feet at once in a bridge. 4. Push the shoulders forward over the hands and drive the hips up. 5. Pull up to standing with arms by the ears, head coming up last. | H24: • Bending the arms as the feet land • Feet landing too close, so the bridge collapses • Throwing the head up first to stand | I24: Home + adult | J24: It goes over through handstand into a deep back arch, so learn it in class first and practise at home only on a mat with an adult nearby once the teacher says she has it; some coaches note it is hard on the lower back if forced. | K24: Strong straight-arm bridge; Handstand with legs together; Stand up from a bridge (with help first); Shoulder and upper-back flexibility
A25: Acro basics | B25: Front limber | C25: Level 2 | D25: Yes | E25: Front limber: 1 hand | F25: A front limber with only one hand on the floor, which needs more strength and balance through the supporting shoulder. | G25: 1. Start in a lunge as for a front limber. 2. Place one hand only and kick to a stacked position over it. 3. Bring the legs together and over into a bridge, supported on one arm. 4. Push through the shoulder and stand up. | H25: • Supporting arm bending • Body twisting off the line • Trying it before a two-handed limber is consistent | I25: Home + adult | J25: It goes over through handstand into a deep back arch, so learn it in class first and practise at home only on a mat with an adult nearby once the teacher says she has it; some coaches note it is hard on the lower back if forced. | K25: Strong straight-arm bridge; Handstand with legs together; Stand up from a bridge (with help first); Shoulder and upper-back flexibility
A26: Acro basics | B26: Elbow stand | C26: Level 1 | E26: Elbow stand: clap feet | F26: I could not find a written definition of this exact term; ask the teacher. From the name it most likely means an elbow stand with the feet tapping or clapping together at the top. | G26: 1. Kneel and place the forearms on the floor shoulder-width apart, palms flat. 2. Walk the feet in until the hips are over the shoulders. 3. Kick up one leg then the other into the elbow stand. 4. Do the foot action the teacher shows, keeping the shoulders pushing away from the floor. 5. Come down one leg at a time. | H26: • Elbows sliding wider than the shoulders • Shoulders sinking toward the floor • Kicking up too hard and rolling over | I26: Home + adult | J26: She balances upside down with her head close to the floor, so practise at a wall or on a mat with an adult nearby once the teacher is happy, and keep the deep-arch versions (hollowback, tick tock) for class until cleared. | K26: Headstand or comfort being upside down; Strong shoulders (dolphin/forearm plank); Shoulder flexibility to stack hips over the elbows; Back flexibility for the C-curve and hollowback shapes | L26: Yes
A27: Acro basics | B27: Elbow stand | C27: Level 2 | D27: Yes | E27: Elbow stand: double stag | F27: An elbow stand with the legs split front and back and both knees bent, like a double stag leap upside down. Inferred from the stag shape; ask the teacher to confirm. | G27: 1. Kick up to a balanced elbow stand. 2. Split the legs front and back. 3. Bend both knees into the double stag shape. 4. Hold briefly, then straighten and come down. | H27: • Hips dropping as the legs bend • Uneven split • Losing shoulder push | I27: Home + adult | J27: She balances upside down with her head close to the floor, so practise at a wall or on a mat with an adult nearby once the teacher is happy, and keep the deep-arch versions (hollowback, tick tock) for class until cleared. | K27: Headstand or comfort being upside down; Strong shoulders (dolphin/forearm plank); Shoulder flexibility to stack hips over the elbows; Back flexibility for the C-curve and hollowback shapes | L27: Yes
A28: Acro basics | B28: Elbow stand | C28: Level 3 | D28: Yes | E28: Elbow stand: helicopter | F28: Not a standard term I could verify; ask the teacher. Elsewhere on the chart 'helicopter' means a leg switch while upside down, so it may be a leg switch in the elbow stand, but I could not confirm it. | G28: 1. Ask the teacher to demonstrate. 2. Requires a steady elbow stand first. 3. Practise only the progression the teacher sets. | H28: • Attempting it before the basic elbow stand is steady | I28: Home + adult | J28: She balances upside down with her head close to the floor, so practise at a wall or on a mat with an adult nearby once the teacher is happy, and keep the deep-arch versions (hollowback, tick tock) for class until cleared. | K28: Headstand or comfort being upside down; Strong shoulders (dolphin/forearm plank); Shoulder flexibility to stack hips over the elbows; Back flexibility for the C-curve and hollowback shapes | L28: Yes
A29: Acro basics | B29: Elbow stand | C29: Level 4 | E29: Elbow stand: elbow tick tock | F29: Not a standard term I could verify; ask the teacher. A standard tick tock rocks from handstand down to a bridge and back up to handstand; this may be the forearm version, but I found no source describing it. | G29: 1. Ask the teacher to demonstrate. 2. A regular tick tock needs strong back, shoulder and hip flexor flexibility. 3. Learn it only in class with spotting. | H29: • Attempting deep back arches without enough flexibility or a spotter | I29: Home + adult | J29: She balances upside down with her head close to the floor, so practise at a wall or on a mat with an adult nearby once the teacher is happy, and keep the deep-arch versions (hollowback, tick tock) for class until cleared. | K29: Headstand or comfort being upside down; Strong shoulders (dolphin/forearm plank); Shoulder flexibility to stack hips over the elbows; Back flexibility for the C-curve and hollowback shapes | L29: Yes
A30: Acro basics | B30: Elbow stand | C30: Level 2 | D30: Yes | E30: Elbow stand: C-curve | F30: I could not find a written definition of this exact term; ask the teacher. From the name it most likely means an elbow stand with the back gently arched so the body forms a C shape, a step toward the deeper hollowback. | G30: 1. Kick up to a balanced elbow stand. 2. Keep pushing the shoulders up and the elbows in. 3. Let the back arch gently as the legs lower slightly behind, forming a C shape (as shown by the teacher). 4. Hold briefly and return to straight before coming down. | H30: • Arching from the lower back only • Shoulders collapsing as the legs go back | I30: Home + adult | J30: She balances upside down with her head close to the floor, so practise at a wall or on a mat with an adult nearby once the teacher is happy, and keep the deep-arch versions (hollowback, tick tock) for class until cleared. | K30: Headstand or comfort being upside down; Strong shoulders (dolphin/forearm plank); Shoulder flexibility to stack hips over the elbows; Back flexibility for the C-curve and hollowback shapes | L30: Yes
A31: Acro basics | B31: Elbow stand | C31: Level 4 | E31: Elbow stand: hollowback | F31: A deep backbend in the forearm stand: the chest pushes through, the back arches strongly and the legs drop toward or over the head. | G31: 1. Build a steady forearm stand first, often against a wall. 2. Push the chest forward through the arms while keeping the shoulders lifted. 3. Arch through the whole spine and let the legs lower behind toward the head. 4. Hold with control and return to straight, or come down as the teacher directs. | H31: • Dumping into the lower back instead of arching the whole spine • Shoulders sinking so the head touches the floor • Trying it before a comfortable forearm stand | I31: Home + adult | J31: She balances upside down with her head close to the floor, so practise at a wall or on a mat with an adult nearby once the teacher is happy, and keep the deep-arch versions (hollowback, tick tock) for class until cleared. | K31: Headstand or comfort being upside down; Strong shoulders (dolphin/forearm plank); Shoulder flexibility to stack hips over the elbows; Back flexibility for the C-curve and hollowback shapes
A32: Acro basics | B32: Elbow cartwheel | C32: Level 1 | E32: Elbow cartwheel: from knees | F32: The beginner version: starting kneeling, placing the forearms one after the other and rolling the legs over in a cartwheel line. | G32: 1. Kneel side-on to the line with arms ready. 2. Place the first forearm then the second on the floor in a line, hands flat. 3. Lift the hips over the elbows and swing the legs over in a straddle. 4. Land one foot at a time on the far side. 5. Keep the head lifted off the floor throughout. | H32: • Head touching or resting on the floor • Elbows too close together, so she rolls sideways • Legs bent and dragging | I32: Home + adult | J32: Her head passes close to the floor while she is upside down, so practise on a mat with an adult nearby once the teacher says she has it; keep the helicopter version for class. | K32: Regular cartwheel; Comfort in an elbow stand or headstand; Forearm and shoulder strength; Straddle flexibility
A33: Acro basics | B33: Elbow cartwheel | C33: Level 2 | D33: Yes | E33: Elbow cartwheel: from standing | F33: The same skill started from standing or a lunge, so the dancer lowers down to the forearms with control before going over. | G33: 1. Start in a lunge with arms up. 2. Reach down and place the forearms in a line, lowering with control. 3. Kick the legs over in a wide straddle, hips over the elbows. 4. Land one foot at a time and stand up. | H33: • Dropping onto the forearms with no control • Head going to the floor • Not kicking high enough to get the hips over | I33: Home + adult | J33: Her head passes close to the floor while she is upside down, so practise on a mat with an adult nearby once the teacher says she has it; keep the helicopter version for class. | K33: Regular cartwheel; Comfort in an elbow stand or headstand; Forearm and shoulder strength; Straddle flexibility
A34: Acro basics | B34: Elbow cartwheel | C34: Level 3 | D34: Yes | E34: Elbow cartwheel: one elbow from standing | F34: An elbow cartwheel from standing using only one forearm on the floor, which needs much more shoulder strength and balance. | G34: 1. Start in a lunge. 2. Lower onto one forearm only, the other arm held clear. 3. Kick over with straight legs, hips stacked over the supporting elbow. 4. Land one foot at a time. | H34: • Supporting shoulder collapsing • Rolling off the line • Trying it before the two-elbow version is solid | I34: Home + adult | J34: Her head passes close to the floor while she is upside down, so practise on a mat with an adult nearby once the teacher says she has it; keep the helicopter version for class. | K34: Regular cartwheel; Comfort in an elbow stand or headstand; Forearm and shoulder strength; Straddle flexibility
A35: Acro basics | B35: Elbow cartwheel | C35: Level 4 | E35: Elbow cartwheel: helicopter | F35: Not a standard term I could verify; ask the teacher. On the chart 'helicopter' also applies to cartwheels, where it means a leg switch while upside down, so this may be the elbow-cartwheel version, but I found no source for it. | G35: 1. Ask the teacher to demonstrate. 2. Requires a consistent elbow cartwheel and a helicopter cartwheel. 3. Practise only in class with the teacher's progressions. | H35: • Attempting it before both base skills are solid | I35: Home + adult | J35: Her head passes close to the floor while she is upside down, so practise on a mat with an adult nearby once the teacher says she has it; keep the helicopter version for class. | K35: Regular cartwheel; Comfort in an elbow stand or headstand; Forearm and shoulder strength; Straddle flexibility | L35: Yes
A36: Acro basics | B36: Headstand | C36: Level 1 | E36: Headstand | F36: The basic tripod headstand: head and hands form a triangle, body held straight and still above. | G36: 1. Kneel on a mat and place the hands shoulder-width apart, with the front of the top of the head on the mat ahead of them so the three points form a triangle. 2. Straighten the legs and walk the feet in toward the elbows, hips rising over the shoulders. 3. Rest one knee then the other on the elbows (the tripod or 'frog' balance). 4. Tighten the tummy and slowly lift the legs up together until the body is straight. 5. To come down, bend the knees, lower the feet with control, or tuck the chin and roll out. | H36: • Too much weight on the head instead of pressing through the hands • Head and hands in a straight line instead of a triangle, so she tips sideways • Kicking up instead of lifting slowly with a tight core | I36: Home + adult | J36: A tripod headstand is a still hold that is fine on a proper mat with an adult nearby once the teacher is happy with it; the Level 4 headspin/drill loads the neck while spinning and is class-only. The headspin / drill puts spinning load on the head and neck: class only. | K36: Strong core (hollow hold); Shoulder and arm strength to take most of the weight in the hands; Confident tuck and forward roll to come out safely; Tripod balance with knees resting on elbows
A37: Acro basics | B37: Headstand | C37: Level 2 | D37: Yes | E37: Headstand: from crow | F37: Starts in a crow balance (knees on the backs of the arms) and moves into the headstand without putting the feet down. | G37: 1. Hold a steady crow. 2. Lean forward and lower the top of the head to the mat ahead of the hands to make a tripod. 3. Keep the knees resting on the arms for a moment to find balance. 4. Slowly lift the legs up into a straight headstand. 5. Reverse the path or tuck and roll out to finish. | H37: • Dropping onto the head quickly instead of lowering with the arms • Hands too close to the head, so there is no triangle • Arching the back as the legs lift | I37: Home + adult | J37: A tripod headstand is a still hold that is fine on a proper mat with an adult nearby once the teacher is happy with it; the Level 4 headspin/drill loads the neck while spinning and is class-only. The headspin / drill puts spinning load on the head and neck: class only. | K37: Strong core (hollow hold); Shoulder and arm strength to take most of the weight in the hands; Confident tuck and forward roll to come out safely; Tripod balance with knees resting on elbows
A38: Acro basics | B38: Headstand | C38: Level 3 | D38: Yes | E38: Headstand: walking circle | F38: I could not find a written description of this exact variation. It most likely means turning the body all the way round while staying in the headstand by taking small steps with the hands; please confirm the details with the teacher. | G38: 1. Begin in a steady tripod headstand. 2. Keep the body tight and stacked over the head. 3. The teacher will show how the hands step around so the body turns a full circle. 4. Come down with control or tuck and roll out. | H38: • Losing the tight body line while the hands move • Moving the head instead of keeping it as the fixed point | I38: Home + adult | J38: A tripod headstand is a still hold that is fine on a proper mat with an adult nearby once the teacher is happy with it; the Level 4 headspin/drill loads the neck while spinning and is class-only. The headspin / drill puts spinning load on the head and neck: class only. | K38: Strong core (hollow hold); Shoulder and arm strength to take most of the weight in the hands; Confident tuck and forward roll to come out safely; Tripod balance with knees resting on elbows
A39: Acro basics | B39: Headstand | C39: Level 4 | E39: Headstand: headspin / drill | F39: Class-only. A headspin is a breaking power move where the dancer spins on the top of the head while upside down. In breaking slang 'drills' usually means fast, tight headspins, but I could not confirm a source for this in this task, so ask the teacher what she means. | G39: 1. What it looks like: the dancer is upside down on the head, legs up, spinning round. 2. Coaches build it from a very steady tripod headstand and shoulder strength first. 3. Breakers use a beanie or helmet and a smooth floor; the coach teaches the hand push that starts the spin and how to stop and come out safely. 4. Only practised with a coach watching. | H39: • Spinning before the headstand balance is solid • Letting the neck take the force instead of staying tight through the body • Practising without a coach or head protection | I39: Home + adult | J39: A tripod headstand is a still hold that is fine on a proper mat with an adult nearby once the teacher is happy with it; the Level 4 headspin/drill loads the neck while spinning and is class-only. The headspin / drill puts spinning load on the head and neck: class only. | K39: Strong core (hollow hold); Shoulder and arm strength to take most of the weight in the hands; Confident tuck and forward roll to come out safely; Tripod balance with knees resting on elbows | L39: Yes
A40: Acro basics | B40: Headspring | C40: Level 2 | D40: Yes | E40: Headspring: headstand to bridge | F40: The first stage: from a headstand she lets the legs fall over the far side and lands in a bridge, learning the arched shape without the push. | G40: 1. What it looks like: she holds a tripod headstand, lets the legs travel slowly over and lands with feet on the mat in a bridge. 2. Coaches often have her fall onto a soft raised mat first. 3. The coach supports the shoulders and lower back and teaches keeping the head still and the arms pushing. | H40: • Bending the head forward instead of keeping it in place • Collapsing the arms so the neck takes weight • Letting the legs drop fast and crashing into the bridge | I40: Class only | J40: It is a flipping skill that passes over the head and neck, so it is learned only with a coach spotting on proper mats. | K40: Solid tripod headstand; Bridge with straight arms; Forward roll; Core and shoulder strength to push from the floor
...

Sheet Drills
A1: Section | B1: Family | C1: Drill | D1: How | E1: Safety
A2: Acro basics | B2: Handstand | C2: Donkey kicks | D2: From a crouch with hands on the floor, kick both feet up behind and land softly, building toward stacking the hips over the shoulders. | E2: Home
A3: Acro basics | B3: Handstand | C3: Lunge to T-shape | D3: From a lunge, tip forward into a T-shape (arms and back leg in a line) and return, the same entry and exit used for the handstand. | E3: Home
A4: Acro basics | B4: Handstand | C4: Wall walk / chest-to-wall handstand | D4: Walk the feet up the wall facing it and hold a straight handstand, which builds strength and the correct shape. | E4: Home + adult
A5: Acro basics | B5: Handstand | C5: Handstand shape practice at the wall | D5: In a wall handstand, practise the leg shapes (stag, straddle, double stag) one at a time while keeping arms locked. | E5: Home + adult
A6: Acro basics | B6: Handstand | C6: Handstand walking drills | D6: Weight shifts from hand to hand, shoulder shrugs and short assisted walks, as used by handstand-walk coaches before free walking. | E6: Home + adult
A7: Acro basics | B7: Handstand hold | C7: Hollow-body hold | D7: Lie on the back, lift arms and legs slightly with the lower back pressed into the floor, and hold. | E7: Home
A8: Acro basics | B8: Handstand hold | C8: Pike shoulder taps on a box | D8: With feet on a sofa or box and hips over the shoulders, tap one shoulder at a time to build strength under less load. | E8: Home + adult
A9: Acro basics | B9: Handstand hold | C9: Timed chest-to-wall handstand | D9: Walk up the wall facing it and hold a straight line for a timed count, building up toward one minute. | E9: Home + adult
A10: Acro basics | B10: Handstand hold | C10: Wall shoulder taps | D10: In a wall handstand, tap opposite shoulders in slow alternation. | E10: Home + adult
A11: Acro basics | B11: Handstand hold | C11: Handstand pops on a panel mat | D11: Short pushes through the shoulders from handstand onto a panel mat, a drill shared by an Acrobatic Arts teacher; best done in class. | E11: Class only
A12: Acro basics | B12: Cartwheel | C12: Bunny hops / monkey jumps | D12: Hands on the floor, jump the feet sideways over a line, building toward a cartwheel. | E12: Home
... A207: Partner moves | B207: Bluebird | C207: Coach-led progression | D207: Learn the entry, hold and exit in stages in class once the teacher has explained the move. | E207: Class only

Sheet Links
A1: Section | B1: Family | C1: Kind | D1: Title (click to open) | E1: Source | F1: URL
A2: Acro basics | B2: Handstand | C2: video | D2: Handstand Basics for Kids with Coaches Becky and Ethan | E2: YouTube | F2: https://www.youtube.com/watch?v=OwkGFmrWU2U
A3: Acro basics | B3: Handstand | C3: video | D3: The Handstand Shapes YOU Should Be Training | E3: YouTube | F3: https://www.youtube.com/watch?v=UbgxEc4o-i8
A4: Acro basics | B4: Handstand | C4: video | D4: HOW TO HANDSTAND WALK. DRILLS, TIPS AND TRICKS TO LEARN FAST! | E4: YouTube | F4: https://www.youtube.com/watch?v=7I2TEyZl22s
A5: Acro basics | B5: Handstand | C5: article | D5: Handstand (stag and other variations) | E5: Wikiversity | F5: https://en.wikiversity.org/wiki/Handstand
A6: Acro basics | B6: Handstand | C6: article | D6: Discover the Dynamic Levels of Acro Dance at Acrobatic Arts | E6: Acrobatic Arts | F6: https://www.acrobaticarts.com/blog/discover-the-dynamic-levels-of-acro-dance-at-acrobatic-arts
A7: Acro basics | B7: Handstand | C7: pinterest | D7: Handstand drills (gymnastics) ideas | E7: Pinterest | F7: https://www.pinterest.com/ideas/handstand-drills-gymnastics/930342745762/
A8: Acro basics | B8: Handstand | C8: pinterest | D8: Mini acro drills board | E8: Pinterest | F8: https://au.pinterest.com/caitlinmrnjavac/mini-acro-drills/
A9: Acro basics | B9: Handstand hold | C9: video | D9: Gymnastics for kids: How to Do A Handstand | E9: YouTube | F9: https://www.youtube.com/watch?v=1WRcfLWlONQ&pp=0gcJCdgAo7VqN5tD
A10: Acro basics | B10: Handstand hold | C10: article | D10: 4 Drills for Getting Stronger and Better at Handstands | E10: Breaking Muscle | F10: https://breakingmuscle.com/4-drills-for-getting-stronger-and-better-at-handstands/
A11: Acro basics | B11: Handstand hold | C11: article | D11: Handstand Drills | E11: Lost Art of Handbalancing | F11: https://lostartofhandbalancing.com/handstand-drills/
A12: Acro basics | B12: Handstand hold | C12: video | D12: Handstand pops! | E12: Acrobatic Arts (YouTube) | F12: https://www.youtube.com/shorts/WP9Hk5RzoME
... A232: Partner moves | B232: Bluebird | C232: pinterest | D232: Acro dance lifts (ideas) | E232: Pinterest | F232: https://www.pinterest.com/ideas/acro-dance-lifts/904622444319/

Sheet Teacher questions
A1: Level | B1: Move | C1: Family | D1: Teacher's answer | E1: Date asked
A2: Level 1 | B2: Handstand: clap feet | C2: Handstand
A3: Level 2 | B3: Handstand: double stag | C3: Handstand
A4: Level 3 | B4: Handstand: helicopter | C4: Handstand
A5: Level 4 | B5: Handstand: walking (Level 4) | C5: Handstand
A6: Level 3 | B6: Handstand: walking (Level 3) | C6: Handstand
A7: Level 4 | B7: Cartwheel: helicopter walkout | C7: Cartwheel
A8: Level 2 | B8: Round off: brandy | C8: Round off
A9: Level 3 | B9: Round off: bob (no hands) | C9: Round off
A10: Level 3 | B10: Monster walkover | C10: Bridge / walkover
A11: Level 1 | B11: Elbow stand: clap feet | C11: Elbow stand
A12: Level 2 | B12: Elbow stand: double stag | C12: Elbow stand
A13: Level 3 | B13: Elbow stand: helicopter | C13: Elbow stand
... A78: Level 4 | B78: Bluebird: from lean | C78: Bluebird

Sheet Summary
A1: Summary (counts update from the Skills sheet)
B3: Level 1 | C3: Level 2 | D3: Level 3 | E3: Level 4 | F3: Bonus | G3: Total
A4: Moves on the chart | B4: =COUNTIFS(Skills!$C$2:$C$176,"Level 1") -> 26 | C4: =COUNTIFS(Skills!$C$2:$C$176,"Level 2") -> 45 | D4: =COUNTIFS(Skills!$C$2:$C$176,"Level 3") -> 56 | E4: =COUNTIFS(Skills!$C$2:$C$176,"Level 4") -> 46 | F4: =COUNTIFS(Skills!$C$2:$C$176,"Bonus") -> 2 | G4: =SUM(B4:F4) -> 175
A5: Home | B5: =COUNTIFS(Skills!$C$2:$C$176,"Level 1",Skills!$I$2:$I$176,"Home") -> 5 | C5: =COUNTIFS(Skills!$C$2:$C$176,"Level 2",Skills!$I$2:$I$176,"Home") -> 4 | D5: =COUNTIFS(Skills!$C$2:$C$176,"Level 3",Skills!$I$2:$I$176,"Home") -> 2 | E5: =COUNTIFS(Skills!$C$2:$C$176,"Level 4",Skills!$I$2:$I$176,"Home") -> 1 | F5: =COUNTIFS(Skills!$C$2:$C$176,"Bonus",Skills!$I$2:$I$176,"Home") -> 0 | G5: =SUM(B5:F5) -> 12
A6: Home + adult | B6: =COUNTIFS(Skills!$C$2:$C$176,"Level 1",Skills!$I$2:$I$176,"Home + adult") -> 13 | C6: =COUNTIFS(Skills!$C$2:$C$176,"Level 2",Skills!$I$2:$I$176,"Home + adult") -> 22 | D6: =COUNTIFS(Skills!$C$2:$C$176,"Level 3",Skills!$I$2:$I$176,"Home + adult") -> 21 | E6: =COUNTIFS(Skills!$C$2:$C$176,"Level 4",Skills!$I$2:$I$176,"Home + adult") -> 17 | F6: =COUNTIFS(Skills!$C$2:$C$176,"Bonus",Skills!$I$2:$I$176,"Home + adult") -> 2 | G6: =SUM(B6:F6) -> 75
A7: Class only | B7: =COUNTIFS(Skills!$C$2:$C$176,"Level 1",Skills!$I$2:$I$176,"Class only") -> 8 | C7: =COUNTIFS(Skills!$C$2:$C$176,"Level 2",Skills!$I$2:$I$176,"Class only") -> 19 | D7: =COUNTIFS(Skills!$C$2:$C$176,"Level 3",Skills!$I$2:$I$176,"Class only") -> 33 | E7: =COUNTIFS(Skills!$C$2:$C$176,"Level 4",Skills!$I$2:$I$176,"Class only") -> 28 | F7: =COUNTIFS(Skills!$C$2:$C$176,"Bonus",Skills!$I$2:$I$176,"Class only") -> 0 | G7: =SUM(B7:F7) -> 88
A8: Ask the teacher | B8: =COUNTIFS(Skills!$C$2:$C$176,"Level 1",Skills!$L$2:$L$176,"Yes") -> 10 | C8: =COUNTIFS(Skills!$C$2:$C$176,"Level 2",Skills!$L$2:$L$176,"Yes") -> 18 | D8: =COUNTIFS(Skills!$C$2:$C$176,"Level 3",Skills!$L$2:$L$176,"Yes") -> 28 | E8: =COUNTIFS(Skills!$C$2:$C$176,"Level 4",Skills!$L$2:$L$176,"Yes") -> 21 | F8: =COUNTIFS(Skills!$C$2:$C$176,"Bonus",Skills!$L$2:$L$176,"Yes") -> 0 | G8: =SUM(B8:F8) -> 77
A9: Status: Learning | B9: =COUNTIFS(Skills!$C$2:$C$176,"Level 1",Skills!$M$2:$M$176,"Learning") -> 0 | C9: =COUNTIFS(Skills!$C$2:$C$176,"Level 2",Skills!$M$2:$M$176,"Learning") -> 0 | D9: =COUNTIFS(Skills!$C$2:$C$176,"Level 3",Skills!$M$2:$M$176,"Learning") -> 0 | E9: =COUNTIFS(Skills!$C$2:$C$176,"Level 4",Skills!$M$2:$M$176,"Learning") -> 0 | F9: =COUNTIFS(Skills!$C$2:$C$176,"Bonus",Skills!$M$2:$M$176,"Learning") -> 0 | G9: =SUM(B9:F9) -> 0
A10: Status: Clean | B10: =COUNTIFS(Skills!$C$2:$C$176,"Level 1",Skills!$M$2:$M$176,"Clean") -> 0 | C10: =COUNTIFS(Skills!$C$2:$C$176,"Level 2",Skills!$M$2:$M$176,"Clean") -> 0 | D10: =COUNTIFS(Skills!$C$2:$C$176,"Level 3",Skills!$M$2:$M$176,"Clean") -> 0 | E10: =COUNTIFS(Skills!$C$2:$C$176,"Level 4",Skills!$M$2:$M$176,"Clean") -> 0 | F10: =COUNTIFS(Skills!$C$2:$C$176,"Bonus",Skills!$M$2:$M$176,"Clean") -> 0 | G10: =SUM(B10:F10) -> 0
A11: Status: Teacher-checked | B11: =COUNTIFS(Skills!$C$2:$C$176,"Level 1",Skills!$M$2:$M$176,"Teacher-checked") -> 0 | C11: =COUNTIFS(Skills!$C$2:$C$176,"Level 2",Skills!$M$2:$M$176,"Teacher-checked") -> 0 | D11: =COUNTIFS(Skills!$C$2:$C$176,"Level 3",Skills!$M$2:$M$176,"Teacher-checked") -> 0 | E11: =COUNTIFS(Skills!$C$2:$C$176,"Level 4",Skills!$M$2:$M$176,"Teacher-checked") -> 0 | F11: =COUNTIFS(Skills!$C$2:$C$176,"Bonus",Skills!$M$2:$M$176,"Teacher-checked") -> 0 | G11: =SUM(B11:F11) -> 0
A13: Her group (Level 2–3) clean or checked | B13: =IFERROR((COUNTIFS(Skills!$D$2:$D$176,"Yes",Skills!$M$2:$M$176,"Clean")+COUNTIFS(Skills!$D$2:$D$176,"Yes",Skills!$M$2:$M$176,"Teacher-checked"))/COUNTIFS(Skills!$D$2:$D$176,"Yes"),0) -> 0
A14: Share = (Level 2–3 rows with Status Clean or Teacher-checked) ÷ (all Level 2–3 rows). Status is filled in on the Skills sheet.
